<?xml version="1.0"?>

<robot xmlns:xacro="http://wiki.ros.org/xacro" name="ur3">

    <!-- Include XACRO-MACRO FILE OF THE UR3 ROBOT -->
    <xacro:include filename="$(find ur3_ros2_gazebo)/urdf/ur3_macro.urdf.xacro" />
    <!-- Include XACRO-LINEAR AXIS ROS2 CONTROL FILE -->
    <!-- <xacro:include filename="$(find ur3_ros2_gazebo)/urdf/linear_axis_ros2_control.xacro" /> -->

    <!-- Load and initialise UR3 INITIAL POSITIONS FILE: 
    <xacro:arg name="initial_positions_file" default="$(find ur3_ros2_gazebo/config/initial_positions.yaml"/>
    <xacro:property name="initial_positions_file" default="$(arg initial_positions_file)"/> -->
    <!-- IF ADD TO ur3_robot: initial_positions="${load_yaml(initial_positions_file)}" -->
    
    <!-- Initialise PARAMS: -->
    <xacro:arg name="safety_limits" default="false"/>
    <xacro:arg name="safety_pos_margin" default="0.15"/>
    <xacro:arg name="safety_k_position" default="20"/>
    <!-- Simulation parameters -->
    <xacro:arg name="use_fake_hardware" default="false" />
    <xacro:arg name="fake_sensor_commands" default="false" />
    <xacro:arg name="sim_gazebo" default="true" />
    
    <!-- Initialise UR3 ROBOT .urdf -->
    <xacro:ur3_robot
        prefix = ""
        safety_limits="$(arg safety_limits)"
        safety_pos_margin="$(arg safety_pos_margin)"
        safety_k_position="$(arg safety_k_position)"
        use_fake_hardware="$(arg use_fake_hardware)"
        fake_sensor_commands="$(arg fake_sensor_commands)"
    />

    <!-- Gazebo plugins -->
    <xacro:if value="$(arg sim_gazebo)">
      <gazebo>
        <plugin filename="libgazebo_ros2_control.so" name="gazebo_ros2_control">
          <robot_sim_type>gazebo_ros2_control/GazeboSystem</robot_sim_type>
          <parameters>$(find ur3_ros2_gazebo)/config/ur3_controller.yaml</parameters>
        </plugin>
      </gazebo>
    </xacro:if>

    <link name="world"/>

    <link name='ur_base'>
      <inertial>
        <origin xyz="0 0 0" rpy="0 0 0"/>
        <mass value="100"/>
        <inertia ixx="0.01"  ixy="0"  ixz="0" iyy="0.01" iyz="0" izz="0.01" />
      </inertial>
      <collision name='collision'>
        <origin xyz="0 0 0" rpy=" 0 0 0"/> 
        <geometry>
          <box size = "0.2 0.2 1.3"/>
        </geometry>
      </collision>
      <visual name='chassis_visual'>
        <origin xyz="0 0 0" rpy=" 0 0 0"/>
        <geometry>
          <box size = "0.2 0.2 1.3"/>
        </geometry>
        <material name="red">
          <color rgba="1 0 0 1"/>
        </material>
      </visual>
    </link>

    <!-- Linear 7th axis links -->
    <link name="base_linear_axis">
        <visual>
            <geometry>
                <mesh filename="file://$(find ur3_ros2_gazebo)/meshes/visual/linear_axis/simplified_static_parts.stl" scale="0.001 0.001 0.001"/>
            </geometry>
            <material name="Aluminum">
              <color rgba="0.81 0.83 0.85 1.0"/>
            </material>
        </visual>
        <collision>
          <geometry>
            <mesh filename="file://$(find ur3_ros2_gazebo)/meshes/visual/linear_axis/simplified_static_parts.stl" scale="0.001 0.001 0.001"/>
          </geometry>
        </collision>
       <inertial>
          <mass value="0.5"/>
         <inertia ixx="0.0" ixy="0.0" ixz="0.0" iyy="0.0" iyz="0.0" izz="0.0"/>
       </inertial>
    </link>

    <link name="cobot_base">
        <visual>
            <geometry>
                <mesh filename="file://$(find ur3_ros2_gazebo)/meshes/visual/linear_axis/simplified_dynamic_parts.stl" scale="0.001 0.001 0.001"/>
            </geometry>
            <material name="Aluminum_base">
              <color rgba="0.57 0.59 0.6 1.0"/>
            </material>
        </visual>
        <collision>
          <geometry>
            <mesh filename="file://$(find ur3_ros2_gazebo)/meshes/visual/linear_axis/simplified_dynamic_parts.stl" scale="0.001 0.001 0.001"/>
          </geometry>
        </collision>
       <inertial>
          <mass value="0.5"/>
         <inertia ixx="0.002211" ixy="0.0" ixz="0.0" iyy="0.001673" iyz="0.0" izz="0.00387"/>
       </inertial>
    </link>

  <gazebo reference="ur_base">
    <material>Gazebo/Red</material>
  </gazebo>

  <joint name="world_joint" type="fixed">
    <parent link="world" />
    <child link = "ur_base" />
    <origin xyz="0.0 0.0 0.65" rpy="0.0 0.0 0.0" />
  </joint>

  <joint name="ur_joint" type="fixed">
    <parent link="ur_base" />
    <child link = "base_linear_axis" />
    <origin xyz="0.0 0.0 0.655" rpy="0.0 0.0 0.0" /> 
  </joint>

  <!-- Linear 7th axis joints -->
  <joint name="base_axis_joint" type="prismatic">
        <parent link="base_linear_axis"/>
        <child link="cobot_base"/>
        <axis xyz="0 1 0"/>
        <limit lower="0" upper="0.34" velocity="0.5" effort="1000.0"/>
        <origin xyz="0 0.16 0" rpy="0 0 3.1415"/>
  </joint>

  <joint name="cobot_base-base_link_joint" type="fixed">
    <parent link="cobot_base" />
    <child link = "base_link" />
    <origin xyz="0.0 0.0 0.04" rpy="0.0 0.0 0.0" /> 
  </joint>

</robot>